Workbook

Sheet employee_salary_dataset
A1: EmpID | B1: First_Name | C1: Last_Name | D1: Department | E1: Experience_Years | F1: Education_Level | G1: Age | H1: Gender | I1: City | J1: Monthly_Salary | K1: Contact NO
A2: Emp101 | B2: KATAMASETTI | C2: MAHALAKSHMI | D2: Marketing | E2: 15 | F2: Master | G2: 53 | H2: Female | I2: Delhi | J2: 111416 | K2: +91 9989252836
A3: Emp102 | B3: GANTA | C3: SAI BINDU | D3: Operations | E3: 7 | F3: Bachelor | G3: 25 | H3: Female | I3: Bangalore | J3: 95271 | K3: +91 9989252837
A4: Emp103 | B4: GANGUMALLA | C4: MYTHRI | D4: IT | E4: 12 | F4: High School | G4: 51 | H4: Female | I4: Hyderabad | J4: 69064 | K4: +91 9989252837
A5: Emp104 | B5: GANI | C5: AMAR | D5: Operations | E5: 8 | F5: PhD | G5: 44 | H5: Male | I5: Delhi | J5: 95091 | K5: +91 9989252837
A6: Emp105 | B6: GAMYAM | C6: MITHALI RAJ | D6: Operations | E6: 15 | F6: Master | G6: 36 | H6: Female | I6: Delhi | J6: 132450 | K6: +91 9989252837
A7: Emp106 | B7: GUNTURU | C7: AKBAR | D7: Finance | E7: 3 | F7: High School | G7: 50 | H7: Male | I7: Mumbai | J7: 65818 | K7: +91 9989252837
A8: Emp107 | B8: GUNTURI | C8: ANTHONY | D8: IT | E8: 14 | F8: PhD | G8: 57 | H8: Male | I8: Mumbai | J8: 70525 | K8: +91 9989252837
A9: Emp108 | B9: GANGALAKURRU | C9: MAMITA | D9: IT | E9: 17 | F9: PhD | G9: 34 | H9: Female | I9: Bangalore | J9: 44830 | K9: +91 9989252837
A10: Emp109 | B10: THOTAKURA | C10: SAI | D10: IT | E10: 4 | F10: Bachelor | G10: 53 | H10: Male | I10: Hyderabad | J10: 42429 | K10: +91 9989252837
A11: Emp110 | B11: THOTA | C11: MALLIKHARJUN | D11: Operations | E11: 18 | F11: High School | G11: 28 | H11: Male | I11: Mumbai | J11: 31893 | K11: +91 9989252837
A12: Emp111 | B12: GANTI | C12: ANVESH | D12: Marketing | E12: 8 | F12: PhD | G12: 43 | H12: Male | I12: Delhi | J12: 141381 | K12: +91 9989252837
A13: Emp112 | B13: GAGAM | C13: NITHYA | D13: IT | E13: 4 | F13: Master | G13: 49 | H13: Female | I13: Hyderabad | J13: 104909 | K13: +91 9989252837
... A51: Emp150 | B51: MUSHINI | C51: SATYA | D51: Marketing | E51: 10 | F51: High School | G51: 47 | H51: Female | I51: Bangalore | J51: 121752 | K51: +91 9989252837
J52: =SUBTOTAL(9,J2:J51) -> 4114440
J53: =AVERAGE(J2:J51) -> 82288.8
J54: =MAX(J2:J51) -> 149123
J55: =MIN(J2:J52) -> 28420

Sheet Day-1_Basic_Functions
A1: Level 1: Basic Functions
A3: Task 1
A5: Find the total number of employees. | B5: =COUNTA(Employee[EmpID]) -> 50
A7: Task 2
A9: Find the average monthly salary. | B9: =AVERAGE(Employee[Monthly_Salary]) -> 82288.8
A11: Task 3
A13: Find the highest salary. | B13: =MAX(Employee[Monthly_Salary]) -> 149123
A15: Task 4
A17: Find the lowest salary. | B17: =MIN(Employee[Monthly_Salary]) -> 28420
A19: Task 5
A21: Find the total Salary paid by Company. | B21: =SUM(Employee[Monthly_Salary]) -> 4114440
A23: Task 6
A25: Count the number of male employees. | B25: =COUNTIF(Employee[Gender], "Male") -> 23
A27: Task 7
A29: Count the number of female employees. | B29: =COUNTIF(Employee[Gender], "Female") -> 27
A31: Task 8
A33: Find the average experience. | B33: =AVERAGE(Employee[Experience_Years]) -> 9.9
A35: Task 9
A37: Find the youngest employee. | B37: =MIN(Employee[Age]) -> 22
A39: Task 10
A41: Find the oldest employee. | B41: =MAX(Employee[Age]) -> 57

Sheet Day-2_Logical_Functions
A3: Task 11 (IF)
E4: {=Employee[#Headers]} -> EmpID | F4: First_Name | G4: Last_Name | H4: Department | I4: Experience_Years | J4: Education_Level | K4: Age | L4: Gender | M4: City | N4: Monthly_Salary | O4: Contact NO | P4: High_OR_LOW_Salary | Q4: Exp_SR_JR | R4: Work_Rating | S4: Promotion_Eligibility | T4: Bonus_Eligibility | U4: Salary_Per_Experience_Year
A5: If salary is ≥ 100000, return "High Salary", otherwise "Normal Salary". | E5: {=Employee[EmpID]} -> Emp101 | F5: {=Employee[First_Name]} -> KATAMASETTI | G5: {=Employee[Last_Name]} -> MAHALAKSHMI | H5: {=(Employee[Department])} -> Marketing | I5: {=(Employee[Experience_Years])} -> 15 | J5: {=(Employee[Education_Level])} -> Master | K5: {=(Employee[Age])} -> 53 | L5: {=(Employee[Gender])} -> Female | M5: {=(Employee[City])} -> Delhi | N5: {=(Employee[Monthly_Salary])} -> 111416 | O5: {=IF(Employee[Monthly_Salary] >= 100000, "High Salary", "Normal Salary")} -> High Salary | P5: {=IF(Employee[Experience_Years]>=5,"Senior","Junior")} -> Senior | Q5: {=_xlfn.IFS(Employee[Monthly_Salary] >= 100000,"4.5", Employee[Monthly_Salary] >= 80000,"4.0", Employee[Monthly_Salary] >= 60000,"3.5",Employee[Monthly_Salary] >= 50000,"3.0",Employee[Monthly_Salary] >= 40000,"2.5", Employee[Monthly_Salary] < 40000, "2.0")} -> 4.5 | R5: =IF(AND(I5>=5,Q5>=4),"Eligible","Not Eligible") -> Eligible | S5: =IF(AND(I5>=10,N5>=80000),"Eligible","Not Eligible") -> Eligible | T5: {=IFERROR(ROUND(Employee[Monthly_Salary]/Employee[Experience_Years],2),"Check Data")} -> 7427.73
E6: Emp102 | F6: GANTA | G6: SAI BINDU | H6: Operations | I6: 7 | J6: Bachelor | K6: 25 | L6: Female | M6: Bangalore | N6: 95271 | O6: Normal Salary | P6: Senior | Q6: 4.0 | R6: =IF(AND(I6>=5,Q6>=4),"Eligible","Not Eligible") -> Eligible | S6: =IF(AND(I6>=10,N6>=80000),"Eligible","Not Eligible") -> Not Eligible | T6: 13610.14
A7: Task 12 (IF) | E7: Emp103 | F7: GANGUMALLA | G7: MYTHRI | H7: IT | I7: 12 | J7: High School | K7: 51 | L7: Female | M7: Hyderabad | N7: 69064 | O7: Normal Salary | P7: Senior | Q7: 3.5 | R7: =IF(AND(I7>=5,Q7>=4),"Eligible","Not Eligible") -> Eligible | S7: =IF(AND(I7>=10,N7>=80000),"Eligible","Not Eligible") -> Not Eligible | T7: 5755.33
E8: Emp104 | F8: GANI | G8: AMAR | H8: Operations | I8: 8 | J8: PhD | K8: 44 | L8: Male | M8: Delhi | N8: 95091 | O8: Normal Salary | P8: Senior | Q8: 4.0 | R8: =IF(AND(I8>=5,Q8>=4),"Eligible","Not Eligible") -> Eligible | S8: =IF(AND(I8>=10,N8>=80000),"Eligible","Not Eligible") -> Not Eligible | T8: 11886.38
A9: If experience is ≥ 5 years, return "Senior", otherwise "Junior". | E9: Emp105 | F9: GAMYAM | G9: MITHALI RAJ | H9: Operations | I9: 15 | J9: Master | K9: 36 | L9: Female | M9: Delhi | N9: 132450 | O9: High Salary | P9: Senior | Q9: 4.5 | R9: =IF(AND(I9>=5,Q9>=4),"Eligible","Not Eligible") -> Eligible | S9: =IF(AND(I9>=10,N9>=80000),"Eligible","Not Eligible") -> Eligible | T9: 8830
E10: Emp106 | F10: GUNTURU | G10: AKBAR | H10: Finance | I10: 3 | J10: High School | K10: 50 | L10: Male | M10: Mumbai | N10: 65818 | O10: Normal Salary | P10: Junior | Q10: 3.5 | R10: =IF(AND(I10>=5,Q10>=4),"Eligible","Not Eligible") -> Not Eligible | S10: =IF(AND(I10>=10,N10>=80000),"Eligible","Not Eligible") -> Not Eligible | T10: 21939.33
A11: Task 13 (IFS) | E11: Emp107 | F11: GUNTURI | G11: ANTHONY | H11: IT | I11: 14 | J11: PhD | K11: 57 | L11: Male | M11: Mumbai | N11: 70525 | O11: Normal Salary | P11: Senior | Q11: 3.5 | R11: =IF(AND(I11>=5,Q11>=4),"Eligible","Not Eligible") -> Eligible | S11: =IF(AND(I11>=10,N11>=80000),"Eligible","Not Eligible") -> Not Eligible | T11: 5037.5
E12: Emp108 | F12: GANGALAKURRU | G12: MAMITA | H12: IT | I12: 17 | J12: PhD | K12: 34 | L12: Female | M12: Bangalore | N12: 44830 | O12: Normal Salary | P12: Senior | Q12: 2.5 | R12: =IF(AND(I12>=5,Q12>=4),"Eligible","Not Eligible") -> Eligible | S12: =IF(AND(I12>=10,N12>=80000),"Eligible","Not Eligible") -> Not Eligible | T12: 2637.06
A13: Assign performance grades: | E13: Emp109 | F13: THOTAKURA | G13: SAI | H13: IT | I13: 4 | J13: Bachelor | K13: 53 | L13: Male | M13: Hyderabad | N13: 42429 | O13: Normal Salary | P13: Junior | Q13: 2.5 | R13: =IF(AND(I13>=5,Q13>=4),"Eligible","Not Eligible") -> Not Eligible | S13: =IF(AND(I13>=10,N13>=80000),"Eligible","Not Eligible") -> Not Eligible | T13: 10607.25
E14: Emp110 | F14: THOTA | G14: MALLIKHARJUN | H14: Operations | I14: 18 | J14: High School | K14: 28 | L14: Male | M14: Mumbai | N14: 31893 | O14: Normal Salary | P14: Senior | Q14: 2.0 | R14: =IF(AND(I14>=5,Q14>=4),"Eligible","Not Eligible") -> Eligible | S14: =IF(AND(I14>=10,N14>=80000),"Eligible","Not Eligible") -> Not Eligible | T14: 1771.83
A15: 90+ → A | E15: Emp111 | F15: GANTI | G15: ANVESH | H15: Marketing | I15: 8 | J15: PhD | K15: 43 | L15: Male | M15: Delhi | N15: 141381 | O15: High Salary | P15: Senior | Q15: 4.5 | R15: =IF(AND(I15>=5,Q15>=4),"Eligible","Not Eligible") -> Eligible | S15: =IF(AND(I15>=10,N15>=80000),"Eligible","Not Eligible") -> Not Eligible | T15: 17672.63
A16: 80–89 → B | E16: Emp112 | F16: GAGAM | G16: NITHYA | H16: IT | I16: 4 | J16: Master | K16: 49 | L16: Female | M16: Hyderabad | N16: 104909 | O16: High Salary | P16: Junior | Q16: 4.5 | R16: =IF(AND(I16>=5,Q16>=4),"Eligible","Not Eligible") -> Not Eligible | S16: =IF(AND(I16>=10,N16>=80000),"Eligible","Not Eligible") -> Not Eligible | T16: 26227.25
A17: 70–79 → C | E17: Emp113 | F17: GEDDAM | G17: MEGHANA | H17: Operations | I17: 2 | J17: Master | K17: 23 | L17: Female | M17: Hyderabad | N17: 72333 | O17: Normal Salary | P17: Junior | Q17: 3.5 | R17: =IF(AND(I17>=5,Q17>=4),"Eligible","Not Eligible") -> Not Eligible | S17: =IF(AND(I17>=10,N17>=80000),"Eligible","Not Eligible") -> Not Eligible | T17: 36166.5
A18: 60–69 → D | E18: Emp114 | F18: KHANDAVILLI | G18: SHIRISH | H18: Finance | I18: 6 | J18: Bachelor | K18: 27 | L18: Male | M18: Delhi | N18: 28436 | O18: Normal Salary | P18: Senior | Q18: 2.0 | R18: =IF(AND(I18>=5,Q18>=4),"Eligible","Not Eligible") -> Eligible | S18: =IF(AND(I18>=10,N18>=80000),"Eligible","Not Eligible") -> Not Eligible | T18: 4739.33
A19: Below 60 → Fail | E19: Emp115 | F19: PULLE | G19: SMRITI MANDANA | H19: Marketing | I19: 10 | J19: PhD | K19: 49 | L19: Female | M19: Mumbai | N19: 99290 | O19: Normal Salary | P19: Senior | Q19: 4.0 | R19: =IF(AND(I19>=5,Q19>=4),"Eligible","Not Eligible") -> Eligible | S19: =IF(AND(I19>=10,N19>=80000),"Eligible","Not Eligible") -> Eligible | T19: 9929
E20: Emp116 | F20: YARLAGADDA | G20: RICHA GHOSH | H20: Finance | I20: 4 | J20: High School | K20: 49 | L20: Female | M20: Delhi | N20: 101213 | O20: High Salary | P20: Junior | Q20: 4.5 | R20: =IF(AND(I20>=5,Q20>=4),"Eligible","Not Eligible") -> Not Eligible | S20: =IF(AND(I20>=10,N20>=80000),"Eligible","Not Eligible") -> Not Eligible | T20: 25303.25
A21: Task 14 (AND) | E21: Emp117 | F21: KANCHARLA | G21: SRI CHARANI | H21: Marketing | I21: 18 | J21: Master | K21: 41 | L21: Female | M21: Hyderabad | N21: 30895 | O21: Normal Salary | P21: Senior | Q21: 2.0 | R21: =IF(AND(I21>=5,Q21>=4),"Eligible","Not Eligible") -> Eligible | S21: =IF(AND(I21>=10,N21>=80000),"Eligible","Not Eligible") -> Not Eligible | T21: 1716.39
E22: Emp118 | F22: KUNCHE | G22: KAUR | H22: Operations | I22: 12 | J22: PhD | K22: 51 | L22: Female | M22: Chennai | N22: 44738 | O22: Normal Salary | P22: Senior | Q22: 2.5 | R22: =IF(AND(I22>=5,Q22>=4),"Eligible","Not Eligible") -> Eligible | S22: =IF(AND(I22>=10,N22>=80000),"Eligible","Not Eligible") -> Not Eligible | T22: 3728.17
A23: Promotion Eligible if: | E23: Emp119 | F23: KAMBAMPATI | G23: SAHIL | H23: HR | I23: 2 | J23: PhD | K23: 32 | L23: Male | M23: Chennai | N23: 55746 | O23: Normal Salary | P23: Junior | Q23: 3.0 | R23: =IF(AND(I23>=5,Q23>=4),"Eligible","Not Eligible") -> Not Eligible | S23: =IF(AND(I23>=10,N23>=80000),"Eligible","Not Eligible") -> Not Eligible | T23: 27873
E24: Emp120 | F24: AVANTHI | G24: MURALI | H24: Marketing | I24: 10 | J24: Bachelor | K24: 49 | L24: Male | M24: Bangalore | N24: 74377 | O24: Normal Salary | P24: Senior | Q24: 3.5 | R24: =IF(AND(I24>=5,Q24>=4),"Eligible","Not Eligible") -> Eligible | S24: =IF(AND(I24>=10,N24>=80000),"Eligible","Not Eligible") -> Not Eligible | T24: 7437.7
A25: Experience ≥ 5 years | E25: Emp121 | F25: ANNAVARAM | G25: PRIYANKA KAUR | H25: Finance | I25: 4 | J25: Master | K25: 46 | L25: Female | M25: Delhi | N25: 73404 | O25: Normal Salary | P25: Junior | Q25: 3.5 | R25: =IF(AND(I25>=5,Q25>=4),"Eligible","Not Eligible") -> Not Eligible | S25: =IF(AND(I25>=10,N25>=80000),"Eligible","Not Eligible") -> Not Eligible | T25: 18351
A26: Performance Rating ≥ 4 | E26: Emp122 | F26: ANANTHAPALLI | G26: NAMRATA | H26: Operations | I26: 14 | J26: Master | K26: 54 | L26: Female | M26: Delhi | N26: 79045 | O26: Normal Salary | P26: Senior | Q26: 3.5 | R26: =IF(AND(I26>=5,Q26>=4),"Eligible","Not Eligible") -> Eligible | S26: =IF(AND(I26>=10,N26>=80000),"Eligible","Not Eligible") -> Not Eligible | T26: 5646.07
E27: Emp123 | F27: YERRAMSETTY | G27: KRISHNA | H27: Marketing | I27: 16 | J27: High School | K27: 22 | L27: Male | M27: Bangalore | N27: 122888 | O27: High Salary | P27: Senior | Q27: 4.5 | R27: =IF(AND(I27>=5,Q27>=4),"Eligible","Not Eligible") -> Eligible | S27: =IF(AND(I27>=10,N27>=80000),"Eligible","Not Eligible") -> Eligible | T27: 7680.5
A28: Task 15 (OR) | E28: Emp124 | F28: ADAPA | G28: VISHNU | H28: HR | I28: 15 | J28: Master | K28: 48 | L28: Male | M28: Bangalore | N28: 64790 | O28: Normal Salary | P28: Senior | Q28: 3.5 | R28: =IF(AND(I28>=5,Q28>=4),"Eligible","Not Eligible") -> Eligible | S28: =IF(AND(I28>=10,N28>=80000),"Eligible","Not Eligible") -> Not Eligible | T28: 4319.33
E29: Emp125 | F29: RAYUDU | G29: PRAGNYA | H29: HR | I29: 8 | J29: High School | K29: 34 | L29: Female | M29: Bangalore | N29: 132455 | O29: High Salary | P29: Senior | Q29: 4.5 | R29: =IF(AND(I29>=5,Q29>=4),"Eligible","Not Eligible") -> Eligible | S29: =IF(AND(I29>=10,N29>=80000),"Eligible","Not Eligible") -> Not Eligible | T29: 16556.88
A30: Bonus Eligible if: | E30: Emp126 | F30: ALLURI | G30: VIVEK | H30: IT | I30: 14 | J30: Master | K30: 24 | L30: Male | M30: Hyderabad | N30: 30600 | O30: Normal Salary | P30: Senior | Q30: 2.0 | R30: =IF(AND(I30>=5,Q30>=4),"Eligible","Not Eligible") -> Eligible | S30: =IF(AND(I30>=10,N30>=80000),"Eligible","Not Eligible") -> Not Eligible | T30: 2185.71
E31: Emp127 | F31: PENMASTA | G31: LILLY | H31: IT | I31: 8 | J31: Bachelor | K31: 27 | L31: Female | M31: Delhi | N31: 119660 | O31: High Salary | P31: Senior | Q31: 4.5 | R31: =IF(AND(I31>=5,Q31>=4),"Eligible","Not Eligible") -> Eligible | S31: =IF(AND(I31>=10,N31>=80000),"Eligible","Not Eligible") -> Not Eligible | T31: 14957.5
A32: Salary ≥ 80000 | E32: Emp128 | F32: PATCHAMATLA | G32: RASGNYA | H32: Finance | I32: 16 | J32: Master | K32: 29 | L32: Female | M32: Hyderabad | N32: 118179 | O32: High Salary | P32: Senior | Q32: 4.5 | R32: =IF(AND(I32>=5,Q32>=4),"Eligible","Not Eligible") -> Eligible | S32: =IF(AND(I32>=10,N32>=80000),"Eligible","Not Eligible") -> Eligible | T32: 7386.19
A33: Experience ≥ 10 years | E33: Emp129 | F33: KANDULA | G33: DINESH KUMAR | H33: Marketing | I33: 13 | J33: High School | K33: 48 | L33: Male | M33: Bangalore | N33: 65764 | O33: Normal Salary | P33: Senior | Q33: 3.5 | R33: =IF(AND(I33>=5,Q33>=4),"Eligible","Not Eligible") -> Eligible | S33: =IF(AND(I33>=10,N33>=80000),"Eligible","Not Eligible") -> Not Eligible | T33: 5058.77
E34: Emp130 | F34: KONIDELA | G34: VIKAS | H34: Marketing | I34: 18 | J34: High School | K34: 30 | L34: Male | M34: Delhi | N34: 99543 | O34: Normal Salary | P34: Senior | Q34: 4.0 | R34: =IF(AND(I34>=5,Q34>=4),"Eligible","Not Eligible") -> Eligible | S34: =IF(AND(I34>=10,N34>=80000),"Eligible","Not Eligible") -> Eligible | T34: 5530.17
A35: Task 16 (IFERROR) | E35: Emp131 | F35: ALLU | G35: HIMA BINDU | H35: IT | I35: 15 | J35: Bachelor | K35: 54 | L35: Female | M35: Hyderabad | N35: 70714 | O35: Normal Salary | P35: Senior | Q35: 3.5 | R35: =IF(AND(I35>=5,Q35>=4),"Eligible","Not Eligible") -> Eligible | S35: =IF(AND(I35>=10,N35>=80000),"Eligible","Not Eligible") -> Not Eligible | T35: 4714.27
E36: Emp132 | F36: KUCHI | G36: HEMA SRI | H36: Marketing | I36: 13 | J36: Master | K36: 45 | L36: Female | M36: Hyderabad | N36: 81835 | O36: Normal Salary | P36: Senior | Q36: 4.0 | R36: =IF(AND(I36>=5,Q36>=4),"Eligible","Not Eligible") -> Eligible | S36: =IF(AND(I36>=10,N36>=80000),"Eligible","Not Eligible") -> Eligible | T36: 6295
E37: Emp133 | F37: KUCCHU | G37: SIVA KUMAR | H37: Marketing | I37: 9 | J37: Master | K37: 36 | L37: Male | M37: Bangalore | N37: 127946 | O37: High Salary | P37: Senior | Q37: 4.5 | R37: =IF(AND(I37>=5,Q37>=4),"Eligible","Not Eligible") -> Eligible | S37: =IF(AND(I37>=10,N37>=80000),"Eligible","Not Eligible") -> Not Eligible | T37: 14216.22
E38: Emp134 | F38: DAGGUBATI | G38: SONALI | H38: HR | I38: 15 | J38: Bachelor | K38: 53 | L38: Female | M38: Delhi | N38: 134616 | O38: High Salary | P38: Senior | Q38: 4.5 | R38: =IF(AND(I38>=5,Q38>=4),"Eligible","Not Eligible") -> Eligible | S38: =IF(AND(I38>=10,N38>=80000),"Eligible","Not Eligible") -> Eligible | T38: 8974.4
E39: Emp135 | F39: KANCHE | G39: RAVI SANKAR | H39: IT | I39: 13 | J39: Master | K39: 53 | L39: Male | M39: Bangalore | N39: 130983 | O39: High Salary | P39: Senior | Q39: 4.5 | R39: =IF(AND(I39>=5,Q39>=4),"Eligible","Not Eligible") -> Eligible | S39: =IF(AND(I39>=10,N39>=80000),"Eligible","Not Eligible") -> Eligible | T39: 10075.62
E40: Emp136 | F40: GHATTAMANENI | G40: SAMSKRUTHI | H40: Operations | I40: 1 | J40: Master | K40: 45 | L40: Female | M40: Delhi | N40: 98744 | O40: Normal Salary | P40: Junior | Q40: 4.0 | R40: =IF(AND(I40>=5,Q40>=4),"Eligible","Not Eligible") -> Not Eligible | S40: =IF(AND(I40>=10,N40>=80000),"Eligible","Not Eligible") -> Not Eligible | T40: 98744
E41: Emp137 | F41: NANDAMURI | G41: SRI RAM | H41: IT | I41: 7 | J41: High School | K41: 33 | L41: Male | M41: Chennai | N41: 81491 | O41: Normal Salary | P41: Senior | Q41: 4.0 | R41: =IF(AND(I41>=5,Q41>=4),"Eligible","Not Eligible") -> Eligible | S41: =IF(AND(I41>=10,N41>=80000),"Eligible","Not Eligible") -> Not Eligible | T41: 11641.57
E42: Emp138 | F42: AKKINENI | G42: MADHAV | H42: Operations | I42: 9 | J42: Master | K42: 23 | L42: Male | M42: Mumbai | N42: 149123 | O42: High Salary | P42: Senior | Q42: 4.5 | R42: =IF(AND(I42>=5,Q42>=4),"Eligible","Not Eligible") -> Eligible | S42: =IF(AND(I42>=10,N42>=80000),"Eligible","Not Eligible") -> Not Eligible | T42: 16569.22
...

Sheet Day- 3_Test_Functions
A1: Task: 1 LEFT() | D1: Task: 2 RIGHT() | G1: Task:3 MID() | J1: Task: 4 LEN() | M1: Task: 5 TRIM() | P1: Task: 16 CONCAT() | R1: CONCAT() & LOWER()
A3: Gender First Letter | B3: Extract EmpID | D3: Extract EmpID | E3: Contact No Last 4 digit | G3: Mid Contact No | H3: Name | J3: Contact No | K3: City | M3: Department | N3: Name | P3: Full Name | R3: Email
A4: {=LEFT(Employee[Gender])} -> F | B4: {=LEFT(Employee[EmpID],3)} -> Emp | D4: {=RIGHT(Employee[EmpID],3)} -> 101 | E4: {=RIGHT(Employee[Contact NO],4)} -> 2836 | G4: {=MID(Employee[Contact NO],9,12)} -> 252836 | H4: {=MID(Employee[Last_Name],1,3)} -> MAH | J4: {=LEN(Employee[Contact NO])} -> 14 | K4: {=LEN(Employee[City])} -> 5 | M4: {=TRIM(Employee[Department])} -> Marketing | N4: {=TRIM(Employee[Last_Name])} -> MAHALAKSHMI | P4: =_xlfn.CONCAT(employee_salary_dataset!B2," ",employee_salary_dataset!C2) -> KATAMASETTI MAHALAKSHMI | R4: =LOWER(_xlfn.CONCAT(employee_salary_dataset!B2,".",employee_salary_dataset!C2,"@gmail.com")) -> katamasetti.mahalakshmi@gmail.com
A5: F | B5: Emp | D5: 102 | E5: 2837 | G5: 252837 | H5: SAI | J5: 14 | K5: 9 | M5: Operations | N5: SAI BINDU | P5: =_xlfn.CONCAT(employee_salary_dataset!B3," ",employee_salary_dataset!C3) -> GANTA SAI BINDU | R5: =LOWER(_xlfn.CONCAT(employee_salary_dataset!B3,".",employee_salary_dataset!C3,"@gmail.com")) -> ganta.sai bindu@gmail.com
A6: F | B6: Emp | D6: 103 | E6: 2837 | G6: 252837 | H6: MYT | J6: 14 | K6: 9 | M6: IT | N6: MYTHRI | P6: =_xlfn.CONCAT(employee_salary_dataset!B4," ",employee_salary_dataset!C4) -> GANGUMALLA MYTHRI | R6: =LOWER(_xlfn.CONCAT(employee_salary_dataset!B4,".",employee_salary_dataset!C4,"@gmail.com")) -> gangumalla.mythri@gmail.com
A7: M | B7: Emp | D7: 104 | E7: 2837 | G7: 252837 | H7: AMA | J7: 14 | K7: 5 | M7: Operations | N7: AMAR | P7: =_xlfn.CONCAT(employee_salary_dataset!B5," ",employee_salary_dataset!C5) -> GANI AMAR | R7: =LOWER(_xlfn.CONCAT(employee_salary_dataset!B5,".",employee_salary_dataset!C5,"@gmail.com")) -> gani.amar@gmail.com
A8: F | B8: Emp | D8: 105 | E8: 2837 | G8: 252837 | H8: MIT | J8: 14 | K8: 5 | M8: Operations | N8: MITHALI RAJ | P8: =_xlfn.CONCAT(employee_salary_dataset!B6," ",employee_salary_dataset!C6) -> GAMYAM MITHALI RAJ | R8: =LOWER(_xlfn.CONCAT(employee_salary_dataset!B6,".",employee_salary_dataset!C6,"@gmail.com")) -> gamyam.mithali raj@gmail.com
A9: M | B9: Emp | D9: 106 | E9: 2837 | G9: 252837 | H9: AKB | J9: 14 | K9: 6 | M9: Finance | N9: AKBAR | P9: =_xlfn.CONCAT(employee_salary_dataset!B7," ",employee_salary_dataset!C7) -> GUNTURU AKBAR | R9: =LOWER(_xlfn.CONCAT(employee_salary_dataset!B7,".",employee_salary_dataset!C7,"@gmail.com")) -> gunturu.akbar@gmail.com
A10: M | B10: Emp | D10: 107 | E10: 2837 | G10: 252837 | H10: ANT | J10: 14 | K10: 6 | M10: IT | N10: ANTHONY | P10: =_xlfn.CONCAT(employee_salary_dataset!B8," ",employee_salary_dataset!C8) -> GUNTURI ANTHONY | R10: =LOWER(_xlfn.CONCAT(employee_salary_dataset!B8,".",employee_salary_dataset!C8,"@gmail.com")) -> gunturi.anthony@gmail.com
A11: F | B11: Emp | D11: 108 | E11: 2837 | G11: 252837 | H11: MAM | J11: 14 | K11: 9 | M11: IT | N11: MAMITA | P11: =_xlfn.CONCAT(employee_salary_dataset!B9," ",employee_salary_dataset!C9) -> GANGALAKURRU MAMITA | R11: =LOWER(_xlfn.CONCAT(employee_salary_dataset!B9,".",employee_salary_dataset!C9,"@gmail.com")) -> gangalakurru.mamita@gmail.com
A12: M | B12: Emp | D12: 109 | E12: 2837 | G12: 252837 | H12: SAI | J12: 14 | K12: 9 | M12: IT | N12: SAI | P12: =_xlfn.CONCAT(employee_salary_dataset!B10," ",employee_salary_dataset!C10) -> THOTAKURA SAI | R12: =LOWER(_xlfn.CONCAT(employee_salary_dataset!B10,".",employee_salary_dataset!C10,"@gmail.com")) -> thotakura.sai@gmail.com
A13: M | B13: Emp | D13: 110 | E13: 2837 | G13: 252837 | H13: MAL | J13: 14 | K13: 6 | M13: Operations | N13: MALLIKHARJUN | P13: =_xlfn.CONCAT(employee_salary_dataset!B11," ",employee_salary_dataset!C11) -> THOTA MALLIKHARJUN | R13: =LOWER(_xlfn.CONCAT(employee_salary_dataset!B11,".",employee_salary_dataset!C11,"@gmail.com")) -> thota.mallikharjun@gmail.com
A14: M | B14: Emp | D14: 111 | E14: 2837 | G14: 252837 | H14: ANV | J14: 14 | K14: 5 | M14: Marketing | N14: ANVESH | P14: =_xlfn.CONCAT(employee_salary_dataset!B12," ",employee_salary_dataset!C12) -> GANTI ANVESH | R14: =LOWER(_xlfn.CONCAT(employee_salary_dataset!B12,".",employee_salary_dataset!C12,"@gmail.com")) -> ganti.anvesh@gmail.com
A15: F | B15: Emp | D15: 112 | E15: 2837 | G15: 252837 | H15: NIT | J15: 14 | K15: 9 | M15: IT | N15: NITHYA | P15: =_xlfn.CONCAT(employee_salary_dataset!B13," ",employee_salary_dataset!C13) -> GAGAM NITHYA | R15: =LOWER(_xlfn.CONCAT(employee_salary_dataset!B13,".",employee_salary_dataset!C13,"@gmail.com")) -> gagam.nithya@gmail.com
A16: F | B16: Emp | D16: 113 | E16: 2837 | G16: 252837 | H16: MEG | J16: 14 | K16: 9 | M16: Operations | N16: MEGHANA | P16: =_xlfn.CONCAT(employee_salary_dataset!B14," ",employee_salary_dataset!C14) -> GEDDAM MEGHANA | R16: =LOWER(_xlfn.CONCAT(employee_salary_dataset!B14,".",employee_salary_dataset!C14,"@gmail.com")) -> geddam.meghana@gmail.com
... A53: F | B53: Emp | D53: 150 | E53: 2837 | G53: 252837 | H53: SAT | J53: 14 | K53: 9 | M53: Marketing | N53: SATYA | P53: =_xlfn.CONCAT(employee_salary_dataset!B51," ",employee_salary_dataset!C51) -> MUSHINI SATYA | R53: =LOWER(_xlfn.CONCAT(employee_salary_dataset!B51,".",employee_salary_dataset!C51,"@gmail.com")) -> mushini.satya@gmail.com
